Workbook

Sheet 說明
A1: 台灣小公司 Excel 記帳系統
A3: 使用說明
A4: 1. 在「日記簿」頁面輸入所有傳票記錄
A5: 2. 科目表可在「科目表」頁面查看和修改
A6: 3. 「試算表」會自動計算每個科目的借貸合計和餘額
A7: 4. 「資產負債表」和「損益表」會自動根據試算表生成
A8: 5. 「VAT計算」頁面顯示進項稅和銷項稅
A10: 日記簿輸入欄位：
A11: - 傳票號：唯一編號（如 2401001）
A12: - 日期：YYYY/MM/DD 格式
A13: - 摘要：交易說明
A14: - 科目代號：必須是科目表中的代號
... A18: 提醒：借方 = 貸方（雙重記帳原則）

Sheet 科目表
A1: 科目代號 | B1: 科目名稱 | C1: 借/貸 | D1: 科目類別
A2: 1111 | B2: 零用金 | C2: 借 | D2: 資產
A3: 1112 | B3: 銀行存款 | C3: 借 | D3: 資產
A4: 11121 | B4: 銀行存款-國泰 | C4: 借 | D4: 資產
A5: 11122 | B5: 銀行存款-合庫 | C5: 借 | D5: 資產
A6: 11123 | B6: 銀行存款-台銀活存 | C6: 借 | D6: 資產
A7: 11124 | B7: 銀行存款-台銀支存 | C7: 借 | D7: 資產
A8: 1113 | B8: 約當現金 | C8: 借 | D8: 資產
A9: 1114 | B9: 短期投資 | C9: 借 | D9: 資產
A10: 1151 | B10: 透過損益按公允價值衡量之金融資產-流動 | C10: 借 | D10: 資產
A11: 1154 | B11: 避險之金融資產-流動 | C11: 借 | D11: 資產
A12: 1158 | B12: 透過其他綜合損益按公允價值衡量之金融資產-流動 | C12: 借 | D12: 資產
... A225: 9500 | B225: 本期其他綜合損益(稅後淨額) | C225: 借 | D225: 所得稅

Sheet 日記簿
A1: 傳票號 | B1: 日期 | C1: 摘要 | D1: 科目代號 | E1: 科目名稱 | F1: 借方金額 | G1: 貸方金額
A2: 2401001 | B2: 2025/01/01 | C2: 公司創立 | D2: 11121 | E2: =IFERROR(VLOOKUP(D2,科目表!$A:$B,2,FALSE),"") | F2: 1000000
A3: 2401001 | B3: 2025/01/01 | C3: 公司創立 | D3: 3110 | E3: =IFERROR(VLOOKUP(D3,科目表!$A:$B,2,FALSE),"") | G3: 1000000
E4: =IFERROR(VLOOKUP(D4,科目表!$A:$B,2,FALSE),"")
E5: =IFERROR(VLOOKUP(D5,科目表!$A:$B,2,FALSE),"")
E6: =IFERROR(VLOOKUP(D6,科目表!$A:$B,2,FALSE),"")
E7: =IFERROR(VLOOKUP(D7,科目表!$A:$B,2,FALSE),"")
E8: =IFERROR(VLOOKUP(D8,科目表!$A:$B,2,FALSE),"")
E9: =IFERROR(VLOOKUP(D9,科目表!$A:$B,2,FALSE),"")
E10: =IFERROR(VLOOKUP(D10,科目表!$A:$B,2,FALSE),"")
E11: =IFERROR(VLOOKUP(D11,科目表!$A:$B,2,FALSE),"")
E12: =IFERROR(VLOOKUP(D12,科目表!$A:$B,2,FALSE),"")
E13: =IFERROR(VLOOKUP(D13,科目表!$A:$B,2,FALSE),"")
E14: =IFERROR(VLOOKUP(D14,科目表!$A:$B,2,FALSE),"")
E15: =IFERROR(VLOOKUP(D15,科目表!$A:$B,2,FALSE),"")
... E99: =IFERROR(VLOOKUP(D99,科目表!$A:$B,2,FALSE),"")

Sheet 試算表
A1: 科目代號 | B1: 科目名稱 | C1: 借方合計 | D1: 貸方合計 | E1: 餘額 | F1: 科目類別
A2: 1111 | B2: 零用金 | C2: =SUMIFS(日記簿!$F$2:$F$100,日記簿!$D$2:$D$100,A2) | D2: =SUMIFS(日記簿!$G$2:$G$100,日記簿!$D$2:$D$100,A2) | E2: =C2-D2 | F2: 資產
A3: 1112 | B3: 銀行存款 | C3: =SUMIFS(日記簿!$F$2:$F$100,日記簿!$D$2:$D$100,A3) | D3: =SUMIFS(日記簿!$G$2:$G$100,日記簿!$D$2:$D$100,A3) | E3: =C3-D3 | F3: 資產
A4: 11121 | B4: 銀行存款-國泰 | C4: =SUMIFS(日記簿!$F$2:$F$100,日記簿!$D$2:$D$100,A4) | D4: =SUMIFS(日記簿!$G$2:$G$100,日記簿!$D$2:$D$100,A4) | E4: =C4-D4 | F4: 資產
A5: 11122 | B5: 銀行存款-合庫 | C5: =SUMIFS(日記簿!$F$2:$F$100,日記簿!$D$2:$D$100,A5) | D5: =SUMIFS(日記簿!$G$2:$G$100,日記簿!$D$2:$D$100,A5) | E5: =C5-D5 | F5: 資產
A6: 11123 | B6: 銀行存款-台銀活存 | C6: =SUMIFS(日記簿!$F$2:$F$100,日記簿!$D$2:$D$100,A6) | D6: =SUMIFS(日記簿!$G$2:$G$100,日記簿!$D$2:$D$100,A6) | E6: =C6-D6 | F6: 資產
A7: 11124 | B7: 銀行存款-台銀支存 | C7: =SUMIFS(日記簿!$F$2:$F$100,日記簿!$D$2:$D$100,A7) | D7: =SUMIFS(日記簿!$G$2:$G$100,日記簿!$D$2:$D$100,A7) | E7: =C7-D7 | F7: 資產
A8: 1113 | B8: 約當現金 | C8: =SUMIFS(日記簿!$F$2:$F$100,日記簿!$D$2:$D$100,A8) | D8: =SUMIFS(日記簿!$G$2:$G$100,日記簿!$D$2:$D$100,A8) | E8: =C8-D8 | F8: 資產
A9: 1114 | B9: 短期投資 | C9: =SUMIFS(日記簿!$F$2:$F$100,日記簿!$D$2:$D$100,A9) | D9: =SUMIFS(日記簿!$G$2:$G$100,日記簿!$D$2:$D$100,A9) | E9: =C9-D9 | F9: 資產
A10: 1151 | B10: 透過損益按公允價值衡量之金融資產-流動 | C10: =SUMIFS(日記簿!$F$2:$F$100,日記簿!$D$2:$D$100,A10) | D10: =SUMIFS(日記簿!$G$2:$G$100,日記簿!$D$2:$D$100,A10) | E10: =C10-D10 | F10: 資產
A11: 1154 | B11: 避險之金融資產-流動 | C11: =SUMIFS(日記簿!$F$2:$F$100,日記簿!$D$2:$D$100,A11) | D11: =SUMIFS(日記簿!$G$2:$G$100,日記簿!$D$2:$D$100,A11) | E11: =C11-D11 | F11: 資產
A12: 1158 | B12: 透過其他綜合損益按公允價值衡量之金融資產-流動 | C12: =SUMIFS(日記簿!$F$2:$F$100,日記簿!$D$2:$D$100,A12) | D12: =SUMIFS(日記簿!$G$2:$G$100,日記簿!$D$2:$D$100,A12) | E12: =C12-D12 | F12: 資產
A13: 1161 | B13: 按攤銷後成本衡量之金融資產－流動 | C13: =SUMIFS(日記簿!$F$2:$F$100,日記簿!$D$2:$D$100,A13) | D13: =SUMIFS(日記簿!$G$2:$G$100,日記簿!$D$2:$D$100,A13) | E13: =C13-D13 | F13: 資產
A14: 1157 | B14: 其他金融資產-流動 | C14: =SUMIFS(日記簿!$F$2:$F$100,日記簿!$D$2:$D$100,A14) | D14: =SUMIFS(日記簿!$G$2:$G$100,日記簿!$D$2:$D$100,A14) | E14: =C14-D14 | F14: 資產
A15: 1159 | B15: 減:累計減損-金融資產-流動 | C15: =SUMIFS(日記簿!$F$2:$F$100,日記簿!$D$2:$D$100,A15) | D15: =SUMIFS(日記簿!$G$2:$G$100,日記簿!$D$2:$D$100,A15) | E15: =D15-C15 | F15: 資產
A16: 1125 | B16: 合約資產-流動 | C16: =SUMIFS(日記簿!$F$2:$F$100,日記簿!$D$2:$D$100,A16) | D16: =SUMIFS(日記簿!$G$2:$G$100,日記簿!$D$2:$D$100,A16) | E16: =C16-D16 | F16: 資產
A17: 1126 | B17: 減:累計減損-合約資產-流動 | C17: =SUMIFS(日記簿!$F$2:$F$100,日記簿!$D$2:$D$100,A17) | D17: =SUMIFS(日記簿!$G$2:$G$100,日記簿!$D$2:$D$100,A17) | E17: =D17-C17 | F17: 資產
A18: 1121 | B18: 應收票據 | C18: =SUMIFS(日記簿!$F$2:$F$100,日記簿!$D$2:$D$100,A18) | D18: =SUMIFS(日記簿!$G$2:$G$100,日記簿!$D$2:$D$100,A18) | E18: =C18-D18 | F18: 資產
A19: 1122 | B19: 減:備抵呆帳-應收票據 | C19: =SUMIFS(日記簿!$F$2:$F$100,日記簿!$D$2:$D$100,A19) | D19: =SUMIFS(日記簿!$G$2:$G$100,日記簿!$D$2:$D$100,A19) | E19: =D19-C19 | F19: 資產
A20: 1123 | B20: 應收帳款 | C20: =SUMIFS(日記簿!$F$2:$F$100,日記簿!$D$2:$D$100,A20) | D20: =SUMIFS(日記簿!$G$2:$G$100,日記簿!$D$2:$D$100,A20) | E20: =C20-D20 | F20: 資產
A21: 1124 | B21: 減:備抵呆帳-應收帳款 | C21: =SUMIFS(日記簿!$F$2:$F$100,日記簿!$D$2:$D$100,A21) | D21: =SUMIFS(日記簿!$G$2:$G$100,日記簿!$D$2:$D$100,A21) | E21: =D21-C21 | F21: 資產
A22: 1129 | B22: 其他應收款 | C22: =SUMIFS(日記簿!$F$2:$F$100,日記簿!$D$2:$D$100,A22) | D22: =SUMIFS(日記簿!$G$2:$G$100,日記簿!$D$2:$D$100,A22) | E22: =C22-D22 | F22: 資產
A23: 1131 | B23: 商品 | C23: =SUMIFS(日記簿!$F$2:$F$100,日記簿!$D$2:$D$100,A23) | D23: =SUMIFS(日記簿!$G$2:$G$100,日記簿!$D$2:$D$100,A23) | E23: =C23-D23 | F23: 資產
A24: 1132 | B24: 製成品 | C24: =SUMIFS(日記簿!$F$2:$F$100,日記簿!$D$2:$D$100,A24) | D24: =SUMIFS(日記簿!$G$2:$G$100,日記簿!$D$2:$D$100,A24) | E24: =C24-D24 | F24: 資產
A25: 1133 | B25: 在製品 | C25: =SUMIFS(日記簿!$F$2:$F$100,日記簿!$D$2:$D$100,A25) | D25: =SUMIFS(日記簿!$G$2:$G$100,日記簿!$D$2:$D$100,A25) | E25: =C25-D25 | F25: 資產
A26: 1134 | B26: 原料 | C26: =SUMIFS(日記簿!$F$2:$F$100,日記簿!$D$2:$D$100,A26) | D26: =SUMIFS(日記簿!$G$2:$G$100,日記簿!$D$2:$D$100,A26) | E26: =C26-D26 | F26: 資產
A27: 1135 | B27: 物料 | C27: =SUMIFS(日記簿!$F$2:$F$100,日記簿!$D$2:$D$100,A27) | D27: =SUMIFS(日記簿!$G$2:$G$100,日記簿!$D$2:$D$100,A27) | E27: =C27-D27 | F27: 資產
A28: 1136 | B28: 寄銷品 | C28: =SUMIFS(日記簿!$F$2:$F$100,日記簿!$D$2:$D$100,A28) | D28: =SUMIFS(日記簿!$G$2:$G$100,日記簿!$D$2:$D$100,A28) | E28: =C28-D28 | F28: 資產
A29: 1138 | B29: 其他存貨 | C29: =SUMIFS(日記簿!$F$2:$F$100,日記簿!$D$2:$D$100,A29) | D29: =SUMIFS(日記簿!$G$2:$G$100,日記簿!$D$2:$D$100,A29) | E29: =C29-D29 | F29: 資產
A30: 1137 | B30: 備抵存貨跌價損失 | C30: =SUMIFS(日記簿!$F$2:$F$100,日記簿!$D$2:$D$100,A30) | D30: =SUMIFS(日記簿!$G$2:$G$100,日記簿!$D$2:$D$100,A30) | E30: =D30-C30 | F30: 資產
A31: 1141 | B31: 預付費用 | C31: =SUMIFS(日記簿!$F$2:$F$100,日記簿!$D$2:$D$100,A31) | D31: =SUMIFS(日記簿!$G$2:$G$100,日記簿!$D$2:$D$100,A31) | E31: =C31-D31 | F31: 資產
A32: 1142 | B32: 用品盤存 | C32: =SUMIFS(日記簿!$F$2:$F$100,日記簿!$D$2:$D$100,A32) | D32: =SUMIFS(日記簿!$G$2:$G$100,日記簿!$D$2:$D$100,A32) | E32: =C32-D32 | F32: 資產
A33: 1143 | B33: 預付貨款 | C33: =SUMIFS(日記簿!$F$2:$F$100,日記簿!$D$2:$D$100,A33) | D33: =SUMIFS(日記簿!$G$2:$G$100,日記簿!$D$2:$D$100,A33) | E33: =C33-D33 | F33: 資產
A34: 1144 | B34: 進項稅額 | C34: =SUMIFS(日記簿!$F$2:$F$100,日記簿!$D$2:$D$100,A34) | D34: =SUMIFS(日記簿!$G$2:$G$100,日記簿!$D$2:$D$100,A34) | E34: =C34-D34 | F34: 資產
A35: 1145 | B35: 留抵稅額 | C35: =SUMIFS(日記簿!$F$2:$F$100,日記簿!$D$2:$D$100,A35) | D35: =SUMIFS(日記簿!$G$2:$G$100,日記簿!$D$2:$D$100,A35) | E35: =C35-D35 | F35: 資產
A36: 1149 | B36: 其他預付款 | C36: =SUMIFS(日記簿!$F$2:$F$100,日記簿!$D$2:$D$100,A36) | D36: =SUMIFS(日記簿!$G$2:$G$100,日記簿!$D$2:$D$100,A36) | E36: =C36-D36 | F36: 資產
A37: 1191 | B37: 暫付款 | C37: =SUMIFS(日記簿!$F$2:$F$100,日記簿!$D$2:$D$100,A37) | D37: =SUMIFS(日記簿!$G$2:$G$100,日記簿!$D$2:$D$100,A37) | E37: =C37-D37 | F37: 資產
A38: 1192 | B38: 股東往來 | C38: =SUMIFS(日記簿!$F$2:$F$100,日記簿!$D$2:$D$100,A38) | D38: =SUMIFS(日記簿!$G$2:$G$100,日記簿!$D$2:$D$100,A38) | E38: =C38-D38 | F38: 資產
A39: 1193 | B39: 同業往來 | C39: =SUMIFS(日記簿!$F$2:$F$100,日記簿!$D$2:$D$100,A39) | D39: =SUMIFS(日記簿!$G$2:$G$100,日記簿!$D$2:$D$100,A39) | E39: =C39-D39 | F39: 資產
A40: 1199 | B40: 其他流動資產-其他 | C40: =SUMIFS(日記簿!$F$2:$F$100,日記簿!$D$2:$D$100,A40) | D40: =SUMIFS(日記簿!$G$2:$G$100,日記簿!$D$2:$D$100,A40) | E40: =C40-D40 | F40: 資產
...

Sheet 資產負債表
A1: 資產負債表
A2: 截至 2026年04月28日
A4: 資產 | D4: 負債及權益
A5: 流動資產 | B5: =SUMIF(試算表!$F$2:$F$225,"資產",試算表!$E$2:$E$225) | D5: 流動負債 | E5: =SUMIF(試算表!$F$2:$F$225,"負債",試算表!$E$2:$E$225)
A6: 非流動資產 | B6: 0 | D6: 非流動負債 | E6: 0
A7: 資產總計 | B7: =B5+B6 | D7: 股東權益 | E7: =SUMIF(試算表!$F$2:$F$225,"權益",試算表!$E$2:$E$225)
D8: 負債及權益總計 | E8: =E5+E6+E7

Sheet 損益表
A1: 損益表
A2: 自 2026年04月 起
A4: 營業收入 | B4: =SUMIF(試算表!$F$2:$F$225,"收入",試算表!$E$2:$E$225)
A5: 4100 銷貨收入 | B5: =VLOOKUP(4100,試算表!$A:$E,5,FALSE)
A6: 4110 減:銷貨退回 | B6: =VLOOKUP(4110,試算表!$A:$E,5,FALSE)
A7: 4120 減:銷貨折讓 | B7: =VLOOKUP(4120,試算表!$A:$E,5,FALSE)
A8: 4200 勞務收入 | B8: =VLOOKUP(4200,試算表!$A:$E,5,FALSE)
A9: 4300 加工收入 | B9: =VLOOKUP(4300,試算表!$A:$E,5,FALSE)
A10: 4400 工程收入 | B10: =VLOOKUP(4400,試算表!$A:$E,5,FALSE)
A12: 銷貨成本 | B12: =SUMIF(試算表!$F$2:$F$225,"銷貨成本",試算表!$E$2:$E$225)
A13: 5100 銷貨成本 | B13: =VLOOKUP(5100,試算表!$A:$E,5,FALSE)
A14: 5200 勞務成本 | B14: =VLOOKUP(5200,試算表!$A:$E,5,FALSE)
A15: 5300 加工成本 | B15: =VLOOKUP(5300,試算表!$A:$E,5,FALSE)
A16: 5400 工程成本 | B16: =VLOOKUP(5400,試算表!$A:$E,5,FALSE)
A18: 營業毛利 | B18: =B4-B12
A20: 營業費用 | B20: =SUMIF(試算表!$F$2:$F$225,"費用",試算表!$E$2:$E$225)
A21: 6010 薪資支出 | B21: =VLOOKUP(6010,試算表!$A:$E,5,FALSE)
A22: 6020 租金支出 | B22: =VLOOKUP(6020,試算表!$A:$E,5,FALSE)
A23: 6030 文具用品 | B23: =VLOOKUP(6030,試算表!$A:$E,5,FALSE)
A24: 6040 旅費 | B24: =VLOOKUP(6040,試算表!$A:$E,5,FALSE)
A25: 6050 運費 | B25: =VLOOKUP(6050,試算表!$A:$E,5,FALSE)
A26: 6060 郵電費 | B26: =VLOOKUP(6060,試算表!$A:$E,5,FALSE)
A27: 6070 修繕費 | B27: =VLOOKUP(6070,試算表!$A:$E,5,FALSE)
A28: 6080 廣告費 | B28: =VLOOKUP(6080,試算表!$A:$E,5,FALSE)
A29: 6090 水電瓦斯費 | B29: =VLOOKUP(6090,試算表!$A:$E,5,FALSE)
A30: 6100 保險費 | B30: =VLOOKUP(6100,試算表!$A:$E,5,FALSE)
A31: 6110 交際費 | B31: =VLOOKUP(6110,試算表!$A:$E,5,FALSE)
A32: 6120 捐贈 | B32: =VLOOKUP(6120,試算表!$A:$E,5,FALSE)
A33: 6130 稅捐 | B33: =VLOOKUP(6130,試算表!$A:$E,5,FALSE)
A34: 6140 呆帳損失 | B34: =VLOOKUP(6140,試算表!$A:$E,5,FALSE)
A35: 6150 折舊 | B35: =VLOOKUP(6150,試算表!$A:$E,5,FALSE)
A36: 6160 各項耗竭及攤提 | B36: =VLOOKUP(6160,試算表!$A:$E,5,FALSE)
A37: 6170 外銷損失 | B37: =VLOOKUP(6170,試算表!$A:$E,5,FALSE)
A38: 6180 伙食費 | B38: =VLOOKUP(6180,試算表!$A:$E,5,FALSE)
A39: 6190 職工福利 | B39: =VLOOKUP(6190,試算表!$A:$E,5,FALSE)
A40: 6200 研究費 | B40: =VLOOKUP(6200,試算表!$A:$E,5,FALSE)
A41: 6210 佣金支出 | B41: =VLOOKUP(6210,試算表!$A:$E,5,FALSE)
A42: 6220 訓練費 | B42: =VLOOKUP(6220,試算表!$A:$E,5,FALSE)
A43: 6230 其他費用 | B43: =VLOOKUP(6230,試算表!$A:$E,5,FALSE)
A44: 6240 加班費 | B44: =VLOOKUP(6240,試算表!$A:$E,5,FALSE)
...

Sheet VAT計算
A1: 增值稅（VAT）計算
A2: 台灣營業稅率：5%
A4: 進項稅額（科目 1144） | B4: =VLOOKUP("1144",試算表!$A:$E,5,FALSE)
A6: 銷項稅額（科目 2171） | B6: =VLOOKUP("2171",試算表!$A:$E,5,FALSE)
A8: 應繳增值稅 | B8: =B6-B4
A11: 說明：
A12: 應繳 VAT > 0：需繳稅
A13: 應繳 VAT < 0：可退稅（負數表示待退）
A14: 應繳 VAT = 0：不需繳退
