Workbook

Sheet 說明
A1: 台灣小公司 Excel 記帳系統
A3: 使用說明
A4: 1. 在「日記簿」頁面輸入所有傳票記錄
A5: 2. 科目表可在「科目表」頁面查看和修改
A6: 3. 「試算表」會自動計算每個科目的借貸合計和餘額
A7: 4. 「資產負債表」和「損益表」會自動根據試算表生成
A8: 5. 「VAT計算」頁面顯示進項稅和銷項稅
A10: 日記簿輸入欄位：
A11: - 傳票號：唯一編號（如 2401001）
A12: - 日期：YYYY/MM/DD 格式
A13: - 摘要：交易說明
A14: - 科目代號：必須是科目表中的代號
... A18: 提醒：借方 = 貸方（雙重記帳原則）

Sheet 科目表
A1: 科目代號 | B1: 科目名稱 | C1: 借/貸 | D1: 科目類別 | E1: BS分類
A2: 1111 | B2: 零用金 | C2: 借 | D2: 資產 | E2: 流動資產
A3: 1112 | B3: 銀行存款 | C3: 借 | D3: 資產 | E3: 流動資產
A4: 11121 | B4: 銀行存款-國泰 | C4: 借 | D4: 資產 | E4: 流動資產
A5: 11122 | B5: 銀行存款-合庫 | C5: 借 | D5: 資產 | E5: 流動資產
A6: 11123 | B6: 銀行存款-台銀活存 | C6: 借 | D6: 資產 | E6: 流動資產
A7: 11124 | B7: 銀行存款-台銀支存 | C7: 借 | D7: 資產 | E7: 流動資產
A8: 1113 | B8: 約當現金 | C8: 借 | D8: 資產 | E8: 流動資產
A9: 1114 | B9: 短期投資 | C9: 借 | D9: 資產 | E9: 流動資產
A10: 1151 | B10: 透過損益按公允價值衡量之金融資產-流動 | C10: 借 | D10: 資產 | E10: 流動資產
A11: 1154 | B11: 避險之金融資產-流動 | C11: 借 | D11: 資產 | E11: 流動資產
A12: 1158 | B12: 透過其他綜合損益按公允價值衡量之金融資產-流動 | C12: 借 | D12: 資產 | E12: 流動資產
... A138: 3600 | B138: 減:庫藏股票 | C138: 借 | D138: 權益 | E138: 股東權益
A139: 4100 | B139: 銷貨收入 | C139: 貸 | D139: 收入
A140: 4110 | B140: 減:銷貨退回 | C140: 借 | D140: 收入
A141: 4120 | B141: 減:銷貨折讓 | C141: 借 | D141: 收入
A142: 4200 | B142: 勞務收入 | C142: 貸 | D142: 收入
A143: 4300 | B143: 加工收入 | C143: 貸 | D143: 收入
A144: 4400 | B144: 工程收入 | C144: 貸 | D144: 收入
A145: 5100 | B145: 銷貨成本 | C145: 借 | D145: 銷貨成本
A146: 5200 | B146: 勞務成本 | C146: 借 | D146: 銷貨成本
A147: 5300 | B147: 加工成本 | C147: 借 | D147: 銷貨成本
A148: 5400 | B148: 工程成本 | C148: 借 | D148: 銷貨成本
A149: 6010 | B149: 薪資支出 | C149: 借 | D149: 費用
A150: 6020 | B150: 租金支出 | C150: 借 | D150: 費用
... A225: 9500 | B225: 本期其他綜合損益(稅後淨額) | C225: 借 | D225: 所得稅

Sheet 試算表
A1: 科目代號 | B1: 科目名稱 | C1: 借方合計 | D1: 貸方合計 | E1: 餘額 | F1: 科目類別 | G1: BS分類
A2: 1111 | B2: 零用金 | C2: =SUMIFS(日記簿!$F$2:$F$1000,日記簿!$D$2:$D$1000,A2) -> 0 | D2: =SUMIFS(日記簿!$G$2:$G$1000,日記簿!$D$2:$D$1000,A2) -> 0 | E2: =C2-D2 -> 0 | F2: 資產 | G2: 流動資產
A3: 1112 | B3: 銀行存款 | C3: =SUMIFS(日記簿!$F$2:$F$1000,日記簿!$D$2:$D$1000,A3) -> 0 | D3: =SUMIFS(日記簿!$G$2:$G$1000,日記簿!$D$2:$D$1000,A3) -> 0 | E3: =C3-D3 -> 0 | F3: 資產 | G3: 流動資產
A4: 11121 | B4: 銀行存款-國泰 | C4: =SUMIFS(日記簿!$F$2:$F$1000,日記簿!$D$2:$D$1000,A4) -> 19879 | D4: =SUMIFS(日記簿!$G$2:$G$1000,日記簿!$D$2:$D$1000,A4) -> 8782 | E4: =C4-D4 -> 11097 | F4: 資產 | G4: 流動資產
A5: 11122 | B5: 銀行存款-合庫 | C5: =SUMIFS(日記簿!$F$2:$F$1000,日記簿!$D$2:$D$1000,A5) -> 29835 | D5: =SUMIFS(日記簿!$G$2:$G$1000,日記簿!$D$2:$D$1000,A5) -> 28062 | E5: =C5-D5 -> 1773 | F5: 資產 | G5: 流動資產
A6: 11123 | B6: 銀行存款-台銀活存 | C6: =SUMIFS(日記簿!$F$2:$F$1000,日記簿!$D$2:$D$1000,A6) -> 0 | D6: =SUMIFS(日記簿!$G$2:$G$1000,日記簿!$D$2:$D$1000,A6) -> 0 | E6: =C6-D6 -> 0 | F6: 資產 | G6: 流動資產
A7: 11124 | B7: 銀行存款-台銀支存 | C7: =SUMIFS(日記簿!$F$2:$F$1000,日記簿!$D$2:$D$1000,A7) -> 0 | D7: =SUMIFS(日記簿!$G$2:$G$1000,日記簿!$D$2:$D$1000,A7) -> 0 | E7: =C7-D7 -> 0 | F7: 資產 | G7: 流動資產
A8: 1113 | B8: 約當現金 | C8: =SUMIFS(日記簿!$F$2:$F$1000,日記簿!$D$2:$D$1000,A8) -> 0 | D8: =SUMIFS(日記簿!$G$2:$G$1000,日記簿!$D$2:$D$1000,A8) -> 0 | E8: =C8-D8 -> 0 | F8: 資產 | G8: 流動資產
A9: 1114 | B9: 短期投資 | C9: =SUMIFS(日記簿!$F$2:$F$1000,日記簿!$D$2:$D$1000,A9) -> 0 | D9: =SUMIFS(日記簿!$G$2:$G$1000,日記簿!$D$2:$D$1000,A9) -> 0 | E9: =C9-D9 -> 0 | F9: 資產 | G9: 流動資產
A10: 1151 | B10: 透過損益按公允價值衡量之金融資產-流動 | C10: =SUMIFS(日記簿!$F$2:$F$1000,日記簿!$D$2:$D$1000,A10) -> 0 | D10: =SUMIFS(日記簿!$G$2:$G$1000,日記簿!$D$2:$D$1000,A10) -> 0 | E10: =C10-D10 -> 0 | F10: 資產 | G10: 流動資產
A11: 1154 | B11: 避險之金融資產-流動 | C11: =SUMIFS(日記簿!$F$2:$F$1000,日記簿!$D$2:$D$1000,A11) -> 0 | D11: =SUMIFS(日記簿!$G$2:$G$1000,日記簿!$D$2:$D$1000,A11) -> 0 | E11: =C11-D11 -> 0 | F11: 資產 | G11: 流動資產
A12: 1158 | B12: 透過其他綜合損益按公允價值衡量之金融資產-流動 | C12: =SUMIFS(日記簿!$F$2:$F$1000,日記簿!$D$2:$D$1000,A12) -> 0 | D12: =SUMIFS(日記簿!$G$2:$G$1000,日記簿!$D$2:$D$1000,A12) -> 0 | E12: =C12-D12 -> 0 | F12: 資產 | G12: 流動資產
A13: 1161 | B13: 按攤銷後成本衡量之金融資產－流動 | C13: =SUMIFS(日記簿!$F$2:$F$1000,日記簿!$D$2:$D$1000,A13) -> 0 | D13: =SUMIFS(日記簿!$G$2:$G$1000,日記簿!$D$2:$D$1000,A13) -> 0 | E13: =C13-D13 -> 0 | F13: 資產 | G13: 流動資產
A14: 1157 | B14: 其他金融資產-流動 | C14: =SUMIFS(日記簿!$F$2:$F$1000,日記簿!$D$2:$D$1000,A14) -> 0 | D14: =SUMIFS(日記簿!$G$2:$G$1000,日記簿!$D$2:$D$1000,A14) -> 0 | E14: =C14-D14 -> 0 | F14: 資產 | G14: 流動資產
A15: 1159 | B15: 減:累計減損-金融資產-流動 | C15: =SUMIFS(日記簿!$F$2:$F$1000,日記簿!$D$2:$D$1000,A15) -> 0 | D15: =SUMIFS(日記簿!$G$2:$G$1000,日記簿!$D$2:$D$1000,A15) -> 0 | E15: =D15-C15 -> 0 | F15: 資產 | G15: 流動資產
A16: 1125 | B16: 合約資產-流動 | C16: =SUMIFS(日記簿!$F$2:$F$1000,日記簿!$D$2:$D$1000,A16) -> 0 | D16: =SUMIFS(日記簿!$G$2:$G$1000,日記簿!$D$2:$D$1000,A16) -> 0 | E16: =C16-D16 -> 0 | F16: 資產 | G16: 流動資產
A17: 1126 | B17: 減:累計減損-合約資產-流動 | C17: =SUMIFS(日記簿!$F$2:$F$1000,日記簿!$D$2:$D$1000,A17) -> 0 | D17: =SUMIFS(日記簿!$G$2:$G$1000,日記簿!$D$2:$D$1000,A17) -> 0 | E17: =D17-C17 -> 0 | F17: 資產 | G17: 流動資產
A18: 1121 | B18: 應收票據 | C18: =SUMIFS(日記簿!$F$2:$F$1000,日記簿!$D$2:$D$1000,A18) -> 0 | D18: =SUMIFS(日記簿!$G$2:$G$1000,日記簿!$D$2:$D$1000,A18) -> 0 | E18: =C18-D18 -> 0 | F18: 資產 | G18: 流動資產
A19: 1122 | B19: 減:備抵呆帳-應收票據 | C19: =SUMIFS(日記簿!$F$2:$F$1000,日記簿!$D$2:$D$1000,A19) -> 0 | D19: =SUMIFS(日記簿!$G$2:$G$1000,日記簿!$D$2:$D$1000,A19) -> 0 | E19: =D19-C19 -> 0 | F19: 資產 | G19: 流動資產
A20: 1123 | B20: 應收帳款 | C20: =SUMIFS(日記簿!$F$2:$F$1000,日記簿!$D$2:$D$1000,A20) -> 2842717 | D20: =SUMIFS(日記簿!$G$2:$G$1000,日記簿!$D$2:$D$1000,A20) -> 2682788 | E20: =C20-D20 -> 159929 | F20: 資產 | G20: 流動資產
A21: 1124 | B21: 減:備抵呆帳-應收帳款 | C21: =SUMIFS(日記簿!$F$2:$F$1000,日記簿!$D$2:$D$1000,A21) -> 0 | D21: =SUMIFS(日記簿!$G$2:$G$1000,日記簿!$D$2:$D$1000,A21) -> 0 | E21: =D21-C21 -> 0 | F21: 資產 | G21: 流動資產
A22: 1129 | B22: 其他應收款 | C22: =SUMIFS(日記簿!$F$2:$F$1000,日記簿!$D$2:$D$1000,A22) -> 0 | D22: =SUMIFS(日記簿!$G$2:$G$1000,日記簿!$D$2:$D$1000,A22) -> 0 | E22: =C22-D22 -> 0 | F22: 資產 | G22: 流動資產
A23: 1131 | B23: 商品 | C23: =SUMIFS(日記簿!$F$2:$F$1000,日記簿!$D$2:$D$1000,A23) -> 0 | D23: =SUMIFS(日記簿!$G$2:$G$1000,日記簿!$D$2:$D$1000,A23) -> 0 | E23: =C23-D23 -> 0 | F23: 資產 | G23: 流動資產
A24: 1132 | B24: 製成品 | C24: =SUMIFS(日記簿!$F$2:$F$1000,日記簿!$D$2:$D$1000,A24) -> 0 | D24: =SUMIFS(日記簿!$G$2:$G$1000,日記簿!$D$2:$D$1000,A24) -> 0 | E24: =C24-D24 -> 0 | F24: 資產 | G24: 流動資產
A25: 1133 | B25: 在製品 | C25: =SUMIFS(日記簿!$F$2:$F$1000,日記簿!$D$2:$D$1000,A25) -> 0 | D25: =SUMIFS(日記簿!$G$2:$G$1000,日記簿!$D$2:$D$1000,A25) -> 0 | E25: =C25-D25 -> 0 | F25: 資產 | G25: 流動資產
A26: 1134 | B26: 原料 | C26: =SUMIFS(日記簿!$F$2:$F$1000,日記簿!$D$2:$D$1000,A26) -> 0 | D26: =SUMIFS(日記簿!$G$2:$G$1000,日記簿!$D$2:$D$1000,A26) -> 0 | E26: =C26-D26 -> 0 | F26: 資產 | G26: 流動資產
A27: 1135 | B27: 物料 | C27: =SUMIFS(日記簿!$F$2:$F$1000,日記簿!$D$2:$D$1000,A27) -> 0 | D27: =SUMIFS(日記簿!$G$2:$G$1000,日記簿!$D$2:$D$1000,A27) -> 0 | E27: =C27-D27 -> 0 | F27: 資產 | G27: 流動資產
A28: 1136 | B28: 寄銷品 | C28: =SUMIFS(日記簿!$F$2:$F$1000,日記簿!$D$2:$D$1000,A28) -> 0 | D28: =SUMIFS(日記簿!$G$2:$G$1000,日記簿!$D$2:$D$1000,A28) -> 0 | E28: =C28-D28 -> 0 | F28: 資產 | G28: 流動資產
A29: 1138 | B29: 其他存貨 | C29: =SUMIFS(日記簿!$F$2:$F$1000,日記簿!$D$2:$D$1000,A29) -> 0 | D29: =SUMIFS(日記簿!$G$2:$G$1000,日記簿!$D$2:$D$1000,A29) -> 0 | E29: =C29-D29 -> 0 | F29: 資產 | G29: 流動資產
A30: 1137 | B30: 備抵存貨跌價損失 | C30: =SUMIFS(日記簿!$F$2:$F$1000,日記簿!$D$2:$D$1000,A30) -> 0 | D30: =SUMIFS(日記簿!$G$2:$G$1000,日記簿!$D$2:$D$1000,A30) -> 0 | E30: =D30-C30 -> 0 | F30: 資產 | G30: 流動資產
A31: 1141 | B31: 預付費用 | C31: =SUMIFS(日記簿!$F$2:$F$1000,日記簿!$D$2:$D$1000,A31) -> 0 | D31: =SUMIFS(日記簿!$G$2:$G$1000,日記簿!$D$2:$D$1000,A31) -> 0 | E31: =C31-D31 -> 0 | F31: 資產 | G31: 流動資產
A32: 1142 | B32: 用品盤存 | C32: =SUMIFS(日記簿!$F$2:$F$1000,日記簿!$D$2:$D$1000,A32) -> 0 | D32: =SUMIFS(日記簿!$G$2:$G$1000,日記簿!$D$2:$D$1000,A32) -> 0 | E32: =C32-D32 -> 0 | F32: 資產 | G32: 流動資產
A33: 1143 | B33: 預付貨款 | C33: =SUMIFS(日記簿!$F$2:$F$1000,日記簿!$D$2:$D$1000,A33) -> 0 | D33: =SUMIFS(日記簿!$G$2:$G$1000,日記簿!$D$2:$D$1000,A33) -> 0 | E33: =C33-D33 -> 0 | F33: 資產 | G33: 流動資產
A34: 1144 | B34: 進項稅額 | C34: =SUMIFS(日記簿!$F$2:$F$1000,日記簿!$D$2:$D$1000,A34) -> 76948 | D34: =SUMIFS(日記簿!$G$2:$G$1000,日記簿!$D$2:$D$1000,A34) -> 60435 | E34: =C34-D34 -> 16513 | F34: 資產 | G34: 流動資產
A35: 1145 | B35: 留抵稅額 | C35: =SUMIFS(日記簿!$F$2:$F$1000,日記簿!$D$2:$D$1000,A35) -> 0 | D35: =SUMIFS(日記簿!$G$2:$G$1000,日記簿!$D$2:$D$1000,A35) -> 0 | E35: =C35-D35 -> 0 | F35: 資產 | G35: 流動資產
A36: 1149 | B36: 其他預付款 | C36: =SUMIFS(日記簿!$F$2:$F$1000,日記簿!$D$2:$D$1000,A36) -> 0 | D36: =SUMIFS(日記簿!$G$2:$G$1000,日記簿!$D$2:$D$1000,A36) -> 0 | E36: =C36-D36 -> 0 | F36: 資產 | G36: 流動資產
A37: 1191 | B37: 暫付款 | C37: =SUMIFS(日記簿!$F$2:$F$1000,日記簿!$D$2:$D$1000,A37) -> 0 | D37: =SUMIFS(日記簿!$G$2:$G$1000,日記簿!$D$2:$D$1000,A37) -> 0 | E37: =C37-D37 -> 0 | F37: 資產 | G37: 流動資產
A38: 1192 | B38: 股東往來 | C38: =SUMIFS(日記簿!$F$2:$F$1000,日記簿!$D$2:$D$1000,A38) -> 2 | D38: =SUMIFS(日記簿!$G$2:$G$1000,日記簿!$D$2:$D$1000,A38) -> 2 | E38: =C38-D38 -> 0 | F38: 資產 | G38: 流動資產
A39: 1193 | B39: 同業往來 | C39: =SUMIFS(日記簿!$F$2:$F$1000,日記簿!$D$2:$D$1000,A39) -> 0 | D39: =SUMIFS(日記簿!$G$2:$G$1000,日記簿!$D$2:$D$1000,A39) -> 0 | E39: =C39-D39 -> 0 | F39: 資產 | G39: 流動資產
A40: 1199 | B40: 其他流動資產-其他 | C40: =SUMIFS(日記簿!$F$2:$F$1000,日記簿!$D$2:$D$1000,A40) -> 0 | D40: =SUMIFS(日記簿!$G$2:$G$1000,日記簿!$D$2:$D$1000,A40) -> 0 | E40: =C40-D40 -> 0 | F40: 資產 | G40: 流動資產
...

Sheet 日記簿
A1: 傳票號 | B1: 日期 | C1: 摘要 | D1: 科目代號 | E1: 科目名稱 | F1: 借方金額 | G1: 貸方金額
A2: 20250101001 | B2: 2025/01/01 | D2: 11121 | E2: =IFERROR(VLOOKUP(D2,科目表!$A:$B,2,FALSE),"") -> 銀行存款-國泰 | F2: 0
A3: 20250101001 | B3: 2025/01/01 | D3: 3110 | E3: =IFERROR(VLOOKUP(D3,科目表!$A:$B,2,FALSE),"") -> 實收資本 | G3: 0
A4: 20250101001 | B4: 2025/01/01 | C4: 開帳 | D4: 11121 | E4: =IF(D4="","",IFERROR(VLOOKUP(TEXT(D4,"0"),科目表!$A:$B,2,FALSE),"")) -> 銀行存款-國泰 | F4: 19879
A5: 20250101001 | B5: 2025/01/01 | C5: 開帳 | D5: 11122 | E5: =IF(D5="","",IFERROR(VLOOKUP(TEXT(D5,"0"),科目表!$A:$B,2,FALSE),"")) -> 銀行存款-合庫 | F5: 29835
A6: 20250101001 | B6: 2025/01/01 | C6: 開帳 | D6: 1144 | E6: =IF(D6="","",IFERROR(VLOOKUP(TEXT(D6,"0"),科目表!$A:$B,2,FALSE),"")) -> 進項稅額 | F6: 11794
A7: 20250101001 | B7: 2025/01/01 | C7: 開帳 | D7: 1461 | E7: =IF(D7="","",IFERROR(VLOOKUP(TEXT(D7,"0"),科目表!$A:$B,2,FALSE),"")) -> 生財器具 | F7: 300000
A8: 20250101001 | B8: 2025/01/01 | C8: 開帳 | D8: 1462 | E8: =IF(D8="","",IFERROR(VLOOKUP(TEXT(D8,"0"),科目表!$A:$B,2,FALSE),"")) -> 減:累計折舊-生財器具 | G8: 106250
A9: 20250101001 | B9: 2025/01/01 | C9: 開帳 | D9: 1901 | E9: =IF(D9="","",IFERROR(VLOOKUP(TEXT(D9,"0"),科目表!$A:$B,2,FALSE),"")) -> 存出保證金 | F9: 50000
A10: 20250101001 | B10: 2025/01/01 | C10: 開帳 | D10: 2112 | E10: =IF(D10="","",IFERROR(VLOOKUP(TEXT(D10,"0"),科目表!$A:$B,2,FALSE),"")) -> 銀行借款 | G10: 425360
A11: 20250101001 | B11: 2025/01/01 | C11: 開帳 | D11: 2121 | E11: =IF(D11="","",IFERROR(VLOOKUP(TEXT(D11,"0"),科目表!$A:$B,2,FALSE),"")) -> 應付帳款 | G11: 796077
A12: 20250101001 | B12: 2025/01/01 | C12: 開帳 | D12: 1192 | E12: =IF(D12="","",IFERROR(VLOOKUP(TEXT(D12,"0"),科目表!$A:$B,2,FALSE),"")) -> 股東往來 | F12: 1 | G12: 1
A13: 20250101001 | B13: 2025/01/01 | C13: 開帳 | D13: 2134 | E13: =IF(D13="","",IFERROR(VLOOKUP(TEXT(D13,"0"),科目表!$A:$B,2,FALSE),"")) -> 銷項稅額 | G13: 12952
A14: 20250101001 | B14: 2025/01/01 | C14: 開帳 | D14: 3430 | E14: =IF(D14="","",IFERROR(VLOOKUP(TEXT(D14,"0"),科目表!$A:$B,2,FALSE),"")) -> 累積盈虧 | F14: 1 | G14: 1
A15: 20250101001 | B15: 2025/01/01 | C15: 開帳 | D15: 1192 | E15: =IF(D15="","",IFERROR(VLOOKUP(TEXT(D15,"0"),科目表!$A:$B,2,FALSE),"")) -> 股東往來 | F15: 1 | G15: 1
A16: 20250101001 | B16: 2025/01/01 | C16: 開帳 | D16: 3110 | E16: =IF(D16="","",IFERROR(VLOOKUP(TEXT(D16,"0"),科目表!$A:$B,2,FALSE),"")) -> 實收資本 | F16: -1000000
A17: 20250101001 | B17: 2025/01/01 | C17: 開帳 | D17: 3430 | E17: =IF(D17="","",IFERROR(VLOOKUP(TEXT(D17,"0"),科目表!$A:$B,2,FALSE),"")) -> 累積盈虧 | F17: 1 | G17: 1
A18: 20250101001 | B18: 2025/01/01 | C18: 開帳 | D18: 3430 | E18: =IF(D18="","",IFERROR(VLOOKUP(TEXT(D18,"0"),科目表!$A:$B,2,FALSE),"")) -> 累積盈虧 | F18: 1 | G18: 1
A19: 20250101001 | B19: 2025/01/01 | C19: 開帳 | D19: 3430 | E19: =IF(D19="","",IFERROR(VLOOKUP(TEXT(D19,"0"),科目表!$A:$B,2,FALSE),"")) -> 累積盈虧 | G19: -1929131
E20: =IF(D20="","",IFERROR(VLOOKUP(TEXT(D20,"0"),科目表!$A:$B,2,FALSE),""))
E21: =IF(D21="","",IFERROR(VLOOKUP(TEXT(D21,"0"),科目表!$A:$B,2,FALSE),""))
C22: 11-12月營業稅 | D22: 1144 | E22: =IF(D22="","",IFERROR(VLOOKUP(TEXT(D22,"0"),科目表!$A:$B,2,FALSE),"")) -> 進項稅額 | G22: 11794
C23: 11-12月營業稅 | D23: 2134 | E23: =IF(D23="","",IFERROR(VLOOKUP(TEXT(D23,"0"),科目表!$A:$B,2,FALSE),"")) -> 銷項稅額 | F23: 12952
C24: 11-12月營業稅 | D24: 2121 | E24: =IF(D24="","",IFERROR(VLOOKUP(TEXT(D24,"0"),科目表!$A:$B,2,FALSE),"")) -> 應付帳款 | G24: 1158
C25: 1-2月份 | D25: 4100 | E25: =IF(D25="","",IFERROR(VLOOKUP(TEXT(D25,"0"),科目表!$A:$B,2,FALSE),"")) -> 銷貨收入 | G25: 164159
C26: 1-2月份 | D26: 2134 | E26: =IF(D26="","",IFERROR(VLOOKUP(TEXT(D26,"0"),科目表!$A:$B,2,FALSE),"")) -> 銷項稅額 | G26: 8209
C27: 1-2月份 | D27: 1123 | E27: =IF(D27="","",IFERROR(VLOOKUP(TEXT(D27,"0"),科目表!$A:$B,2,FALSE),"")) -> 應收帳款 | F27: 1 | G27: 1
C28: 1-2月份 | D28: 1123 | E28: =IF(D28="","",IFERROR(VLOOKUP(TEXT(D28,"0"),科目表!$A:$B,2,FALSE),"")) -> 應收帳款 | F28: 172368
C29: 1-2月份 | D29: 5100 | E29: =IF(D29="","",IFERROR(VLOOKUP(TEXT(D29,"0"),科目表!$A:$B,2,FALSE),"")) -> 銷貨成本 | F29: 116244
C30: 1-2月份 | D30: 1144 | E30: =IF(D30="","",IFERROR(VLOOKUP(TEXT(D30,"0"),科目表!$A:$B,2,FALSE),"")) -> 進項稅額 | F30: 5809
C31: 1-2月份 | D31: 2121 | E31: =IF(D31="","",IFERROR(VLOOKUP(TEXT(D31,"0"),科目表!$A:$B,2,FALSE),"")) -> 應付帳款 | G31: 122053
C32: 1-2月份 | D32: 1144 | E32: =IF(D32="","",IFERROR(VLOOKUP(TEXT(D32,"0"),科目表!$A:$B,2,FALSE),"")) -> 進項稅額 | G32: 5809
C33: 1-2月份 | D33: 2134 | E33: =IF(D33="","",IFERROR(VLOOKUP(TEXT(D33,"0"),科目表!$A:$B,2,FALSE),"")) -> 銷項稅額 | F33: 8209
C34: 1-2月份營業稅 | D34: 2121 | E34: =IF(D34="","",IFERROR(VLOOKUP(TEXT(D34,"0"),科目表!$A:$B,2,FALSE),"")) -> 應付帳款 | G34: 2400
C35: 3-4月 | D35: 4100 | E35: =IF(D35="","",IFERROR(VLOOKUP(TEXT(D35,"0"),科目表!$A:$B,2,FALSE),"")) -> 銷貨收入 | F35: 217547 | G35: 217547
C36: 3-4月 | D36: 2134 | E36: =IF(D36="","",IFERROR(VLOOKUP(TEXT(D36,"0"),科目表!$A:$B,2,FALSE),"")) -> 銷項稅額 | F36: 10880 | G36: 10880
C37: 3-4月 | D37: 1123 | E37: =IF(D37="","",IFERROR(VLOOKUP(TEXT(D37,"0"),科目表!$A:$B,2,FALSE),"")) -> 應收帳款 | F37: 228427 | G37: 228427
C38: 3-4月 | D38: 1123 | E38: =IF(D38="","",IFERROR(VLOOKUP(TEXT(D38,"0"),科目表!$A:$B,2,FALSE),"")) -> 應收帳款
C39: 3-4月 | D39: 5100 | E39: =IF(D39="","",IFERROR(VLOOKUP(TEXT(D39,"0"),科目表!$A:$B,2,FALSE),"")) -> 銷貨成本 | F39: 122255
C40: 3-4月 | D40: 1144 | E40: =IF(D40="","",IFERROR(VLOOKUP(TEXT(D40,"0"),科目表!$A:$B,2,FALSE),"")) -> 進項稅額 | F40: 6113
...

Sheet 資產負債表
A1: 資產負債表
A2: 截至 2025年12月31日 | B2: 泰瑞莎法迪有限公司
A4: 資產 | D4: 負債及權益
A5: 流動資產 | D5: 流動負債
A6: 1111 零用金 | B6: =IFERROR(VLOOKUP("1111",試算表!$A:$E,5,FALSE),0) -> 0 | D6: 2111 銀行透支 | E6: =IFERROR(VLOOKUP("2111",試算表!$A:$E,5,FALSE),0) -> 0
A7: 1112 銀行存款 | B7: =IFERROR(VLOOKUP("1112",試算表!$A:$E,5,FALSE),0) -> 0 | D7: 2112 銀行借款 | E7: =IFERROR(VLOOKUP("2112",試算表!$A:$E,5,FALSE),0) -> 171000
A8: 11121 銀行存款-國泰 | B8: =IFERROR(VLOOKUP("11121",試算表!$A:$E,5,FALSE),0) -> 11097 | D8: 2113 應付短期票券 | E8: =IFERROR(VLOOKUP("2113",試算表!$A:$E,5,FALSE),0) -> 0
A9: 11122 銀行存款-合庫 | B9: =IFERROR(VLOOKUP("11122",試算表!$A:$E,5,FALSE),0) -> 1773 | D9: 2119 其他短期借款 | E9: =IFERROR(VLOOKUP("2119",試算表!$A:$E,5,FALSE),0) -> 0
A10: 11123 銀行存款-台銀活存 | B10: =IFERROR(VLOOKUP("11123",試算表!$A:$E,5,FALSE),0) -> 0 | D10: 2140 透過損益按公允價值衡量之金融負債-流動 | E10: =IFERROR(VLOOKUP("2140",試算表!$A:$E,5,FALSE),0) -> 0
A11: 11124 銀行存款-台銀支存 | B11: =IFERROR(VLOOKUP("11124",試算表!$A:$E,5,FALSE),0) -> 0 | D11: 2150 避險之金融負債-流動 | E11: =IFERROR(VLOOKUP("2150",試算表!$A:$E,5,FALSE),0) -> 0
A12: 1113 約當現金 | B12: =IFERROR(VLOOKUP("1113",試算表!$A:$E,5,FALSE),0) -> 0 | D12: 2170 特別股負債-流動 | E12: =IFERROR(VLOOKUP("2170",試算表!$A:$E,5,FALSE),0) -> 0
A13: 1114 短期投資 | B13: =IFERROR(VLOOKUP("1114",試算表!$A:$E,5,FALSE),0) -> 0 | D13: 2180 其他金融負債-流動 | E13: =IFERROR(VLOOKUP("2180",試算表!$A:$E,5,FALSE),0) -> 0
A14: 1151 透過損益按公允價值衡量之金融資產-流動 | B14: =IFERROR(VLOOKUP("1151",試算表!$A:$E,5,FALSE),0) -> 0 | D14: 2126 合約負債-流動 | E14: =IFERROR(VLOOKUP("2126",試算表!$A:$E,5,FALSE),0) -> 0
A15: 1154 避險之金融資產-流動 | B15: =IFERROR(VLOOKUP("1154",試算表!$A:$E,5,FALSE),0) -> 0 | D15: 2120 應付票據 | E15: =IFERROR(VLOOKUP("2120",試算表!$A:$E,5,FALSE),0) -> 0
A16: 1158 透過其他綜合損益按公允價值衡量之金融資產-流動 | B16: =IFERROR(VLOOKUP("1158",試算表!$A:$E,5,FALSE),0) -> 0 | D16: 2121 應付帳款 | E16: =IFERROR(VLOOKUP("2121",試算表!$A:$E,5,FALSE),0) -> 1099111
A17: 1161 按攤銷後成本衡量之金融資產－流動 | B17: =IFERROR(VLOOKUP("1161",試算表!$A:$E,5,FALSE),0) -> 0 | D17: 2131 應付費用 | E17: =IFERROR(VLOOKUP("2131",試算表!$A:$E,5,FALSE),0) -> 0
A18: 1157 其他金融資產-流動 | B18: =IFERROR(VLOOKUP("1157",試算表!$A:$E,5,FALSE),0) -> 0 | D18: 2132 應付稅捐 | E18: =IFERROR(VLOOKUP("2132",試算表!$A:$E,5,FALSE),0) -> 0
A19: 1159 減:累計減損-金融資產-流動 | B19: =IFERROR(VLOOKUP("1159",試算表!$A:$E,5,FALSE),0) -> 0 | D19: 2133 應付股利 | E19: =IFERROR(VLOOKUP("2133",試算表!$A:$E,5,FALSE),0) -> 0
A20: 1125 合約資產-流動 | B20: =IFERROR(VLOOKUP("1125",試算表!$A:$E,5,FALSE),0) -> 0 | D20: 2134 銷項稅額 | E20: =IFERROR(VLOOKUP("2134",試算表!$A:$E,5,FALSE),0) -> 25069
A21: 1126 減:累計減損-合約資產-流動 | B21: =IFERROR(VLOOKUP("1126",試算表!$A:$E,5,FALSE),0) -> 0 | D21: 2135 其他應付款-其他 | E21: =IFERROR(VLOOKUP("2135",試算表!$A:$E,5,FALSE),0) -> 0
A22: 1121 應收票據 | B22: =IFERROR(VLOOKUP("1121",試算表!$A:$E,5,FALSE),0) -> 0 | D22: 2137 預收貨款 | E22: =IFERROR(VLOOKUP("2137",試算表!$A:$E,5,FALSE),0) -> 0
A23: 1122 減:備抵呆帳-應收票據 | B23: =IFERROR(VLOOKUP("1122",試算表!$A:$E,5,FALSE),0) -> 0 | D23: 2138 其他預收款 | E23: =IFERROR(VLOOKUP("2138",試算表!$A:$E,5,FALSE),0) -> 0
A24: 1123 應收帳款 | B24: =IFERROR(VLOOKUP("1123",試算表!$A:$E,5,FALSE),0) -> 159929 | D24: 2191 暫收款 | E24: =IFERROR(VLOOKUP("2191",試算表!$A:$E,5,FALSE),0) -> 0
A25: 1124 減:備抵呆帳-應收帳款 | B25: =IFERROR(VLOOKUP("1124",試算表!$A:$E,5,FALSE),0) -> 0 | D25: 2192 股東往來 | E25: =IFERROR(VLOOKUP("2192",試算表!$A:$E,5,FALSE),0) -> 0
A26: 1129 其他應收款 | B26: =IFERROR(VLOOKUP("1129",試算表!$A:$E,5,FALSE),0) -> 0 | D26: 2195 代收款 | E26: =IFERROR(VLOOKUP("2195",試算表!$A:$E,5,FALSE),0) -> 0
A27: 1131 商品 | B27: =IFERROR(VLOOKUP("1131",試算表!$A:$E,5,FALSE),0) -> 0 | D27: 21951 代收款-健保費 | E27: =IFERROR(VLOOKUP("21951",試算表!$A:$E,5,FALSE),0) -> 0
A28: 1132 製成品 | B28: =IFERROR(VLOOKUP("1132",試算表!$A:$E,5,FALSE),0) -> 0 | D28: 21952 代收款-勞保費 | E28: =IFERROR(VLOOKUP("21952",試算表!$A:$E,5,FALSE),0) -> 0
A29: 1133 在製品 | B29: =IFERROR(VLOOKUP("1133",試算表!$A:$E,5,FALSE),0) -> 0 | D29: 21953 代收款-扣繳稅款 | E29: =IFERROR(VLOOKUP("21953",試算表!$A:$E,5,FALSE),0) -> 0
A30: 1134 原料 | B30: =IFERROR(VLOOKUP("1134",試算表!$A:$E,5,FALSE),0) -> 0 | D30: 2196 其他流動負債-其他 | E30: =IFERROR(VLOOKUP("2196",試算表!$A:$E,5,FALSE),0) -> 0
A31: 1135 物料 | B31: =IFERROR(VLOOKUP("1135",試算表!$A:$E,5,FALSE),0) -> 0 | D31: 2210 應付公司債 | E31: =IFERROR(VLOOKUP("2210",試算表!$A:$E,5,FALSE),0) -> 0
A32: 1136 寄銷品 | B32: =IFERROR(VLOOKUP("1136",試算表!$A:$E,5,FALSE),0) -> 0 | D32: 2220 長期借款 | E32: =IFERROR(VLOOKUP("2220",試算表!$A:$E,5,FALSE),0) -> 0
A33: 1138 其他存貨 | B33: =IFERROR(VLOOKUP("1138",試算表!$A:$E,5,FALSE),0) -> 0 | D33: 2230 透過損益按公允價值衡量之金融負債-非流動 | E33: =IFERROR(VLOOKUP("2230",試算表!$A:$E,5,FALSE),0) -> 0
A34: 1137 備抵存貨跌價損失 | B34: =IFERROR(VLOOKUP("1137",試算表!$A:$E,5,FALSE),0) -> 0 | D34: 2240 避險之金融負債-非流動 | E34: =IFERROR(VLOOKUP("2240",試算表!$A:$E,5,FALSE),0) -> 0
A35: 1141 預付費用 | B35: =IFERROR(VLOOKUP("1141",試算表!$A:$E,5,FALSE),0) -> 0 | D35: 2260 特別股負債-非流動 | E35: =IFERROR(VLOOKUP("2260",試算表!$A:$E,5,FALSE),0) -> 0
A36: 1142 用品盤存 | B36: =IFERROR(VLOOKUP("1142",試算表!$A:$E,5,FALSE),0) -> 0 | D36: 2270 其他金融負債-非流動 | E36: =IFERROR(VLOOKUP("2270",試算表!$A:$E,5,FALSE),0) -> 0
A37: 1143 預付貨款 | B37: =IFERROR(VLOOKUP("1143",試算表!$A:$E,5,FALSE),0) -> 0 | D37: 2280 長期應付票據及款項 | E37: =IFERROR(VLOOKUP("2280",試算表!$A:$E,5,FALSE),0) -> 0
A38: 1144 進項稅額 | B38: =IFERROR(VLOOKUP("1144",試算表!$A:$E,5,FALSE),0) -> 16513 | D38: 2281 合約負債-非流動 | E38: =IFERROR(VLOOKUP("2281",試算表!$A:$E,5,FALSE),0) -> 0
A39: 1145 留抵稅額 | B39: =IFERROR(VLOOKUP("1145",試算表!$A:$E,5,FALSE),0) -> 0 | D39: 2290 其他長期負債 | E39: =IFERROR(VLOOKUP("2290",試算表!$A:$E,5,FALSE),0) -> 0
A40: 1149 其他預付款 | B40: =IFERROR(VLOOKUP("1149",試算表!$A:$E,5,FALSE),0) -> 0 | D40: 流動負債合計 | E40: =SUM(E6:E39) -> 1295180
A41: 1191 暫付款 | B41: =IFERROR(VLOOKUP("1191",試算表!$A:$E,5,FALSE),0) -> 0 | D41: 非流動負債
...

Sheet 損益表
A1: 損益表
A2: 自 2025/1/172025/12/31 起 | B2: 泰瑞莎法迪有限公司
A4: 營業收入 | B4: =SUMIF(試算表!$F$2:$F$225,"收入",試算表!$E$2:$E$225) -> 2489793
A5: 4100 銷貨收入 | B5: =VLOOKUP("4100",試算表!$A:$E,5,FALSE) -> 2489793
A6: 4110 減:銷貨退回 | B6: =VLOOKUP("4110",試算表!$A:$E,5,FALSE) -> 0
A7: 4120 減:銷貨折讓 | B7: =VLOOKUP("4120",試算表!$A:$E,5,FALSE) -> 0
A8: 4200 勞務收入 | B8: =VLOOKUP("4200",試算表!$A:$E,5,FALSE) -> 0
A9: 4300 加工收入 | B9: =VLOOKUP("4300",試算表!$A:$E,5,FALSE) -> 0
A10: 4400 工程收入 | B10: =VLOOKUP("4400",試算表!$A:$E,5,FALSE) -> 0
A12: 銷貨成本 | B12: =SUMIF(試算表!$F$2:$F$225,"銷貨成本",試算表!$E$2:$E$225) -> 1166877
A13: 5100 銷貨成本 | B13: =VLOOKUP("5100",試算表!$A:$E,5,FALSE) -> 1166877
A14: 5200 勞務成本 | B14: =VLOOKUP("5200",試算表!$A:$E,5,FALSE) -> 0
A15: 5300 加工成本 | B15: =VLOOKUP("5300",試算表!$A:$E,5,FALSE) -> 0
A16: 5400 工程成本 | B16: =VLOOKUP("5400",試算表!$A:$E,5,FALSE) -> 0
A18: 營業毛利 | B18: =B4-B12 -> 1322916
A20: 營業費用 | B20: =SUMIF(試算表!$F$2:$F$225,"費用",試算表!$E$2:$E$225) -> 1211103
A21: 6010 薪資支出 | B21: =VLOOKUP("6010",試算表!$A:$E,5,FALSE) -> 1068000
A22: 6020 租金支出 | B22: =VLOOKUP("6020",試算表!$A:$E,5,FALSE) -> 0
A23: 6030 文具用品 | B23: =VLOOKUP("6030",試算表!$A:$E,5,FALSE) -> 25605
A24: 6040 旅費 | B24: =VLOOKUP("6040",試算表!$A:$E,5,FALSE) -> 0
A25: 6050 運費 | B25: =VLOOKUP("6050",試算表!$A:$E,5,FALSE) -> 0
A26: 6060 郵電費 | B26: =VLOOKUP("6060",試算表!$A:$E,5,FALSE) -> 0
A27: 6070 修繕費 | B27: =VLOOKUP("6070",試算表!$A:$E,5,FALSE) -> 0
A28: 6080 廣告費 | B28: =VLOOKUP("6080",試算表!$A:$E,5,FALSE) -> 0
A29: 6090 水電瓦斯費 | B29: =VLOOKUP("6090",試算表!$A:$E,5,FALSE) -> 43500
A30: 6100 保險費 | B30: =VLOOKUP("6100",試算表!$A:$E,5,FALSE) -> 51360
A31: 6110 交際費 | B31: =VLOOKUP("6110",試算表!$A:$E,5,FALSE) -> 0
A32: 6120 捐贈 | B32: =VLOOKUP("6120",試算表!$A:$E,5,FALSE) -> 0
A33: 6130 稅捐 | B33: =VLOOKUP("6130",試算表!$A:$E,5,FALSE) -> 0
A34: 6140 呆帳損失 | B34: =VLOOKUP("6140",試算表!$A:$E,5,FALSE) -> 0
A35: 6150 折舊 | B35: =VLOOKUP("6150",試算表!$A:$E,5,FALSE) -> 0
A36: 6160 各項耗竭及攤提 | B36: =VLOOKUP("6160",試算表!$A:$E,5,FALSE) -> 0
A37: 6170 外銷損失 | B37: =VLOOKUP("6170",試算表!$A:$E,5,FALSE) -> 0
A38: 6180 伙食費 | B38: =VLOOKUP("6180",試算表!$A:$E,5,FALSE) -> 0
A39: 6190 職工福利 | B39: =VLOOKUP("6190",試算表!$A:$E,5,FALSE) -> 0
A40: 6200 研究費 | B40: =VLOOKUP("6200",試算表!$A:$E,5,FALSE) -> 0
A41: 6210 佣金支出 | B41: =VLOOKUP("6210",試算表!$A:$E,5,FALSE) -> 0
A42: 6220 訓練費 | B42: =VLOOKUP("6220",試算表!$A:$E,5,FALSE) -> 0
A43: 6230 其他費用 | B43: =VLOOKUP("6230",試算表!$A:$E,5,FALSE) -> 0
A44: 6240 加班費 | B44: =VLOOKUP("6240",試算表!$A:$E,5,FALSE) -> 0
...

Sheet VAT計算
A1: 增值稅（VAT）計算
A2: 台灣營業稅率：5%
A4: 進項稅額（科目 1144） | B4: =VLOOKUP("1144",試算表!$A:$E,5,FALSE) -> 16513
A6: 銷項稅額（科目 2134） | B6: =SUMIF(試算表!A:A,"2134",試算表!E:E) -> 25069
A8: 應繳增值稅 | B8: =B6-B4 -> 8556
A11: 說明：
A12: 應繳 VAT > 0：需繳稅
A13: 應繳 VAT < 0：可退稅（負數表示待退）
A14: 應繳 VAT = 0：不需繳退
